Workbook

Sheet Cover & Instructions
A1: Target Corporation -- Cash Flow & Investment Capacity Decision Cockpit
B3: Prepared | C3: 2026-09-16
B4: Information cutoff | C4: 2026-03-11 (FY2025 10-K, accession 0000027419-26-000016)
B5: Scope | C5: Independent, public-data model built entirely from SEC XBRL filings -- no analyst estimates, no information after the cutoff.
B7: IMPORTANT DISCLAIMER
B8: This workbook is a scenario-based analytical model, NOT investment advice, NOT a price target, and NOT a prediction of Target's actual future results or stock price. DCF outputs (Sheet 11) use illustrative WACC/terminal-growth inputs -- see Sheet 15 (Limitations).
B10: How to use this workbook
B11: 1. Sheet 6 (Forecast Assumptions) has a Scenario Selector dropdown (cell C2) -- choose Base, Upside, or Downside.
B12: 2. Sheets 7-11 (Scenario Forecast through DCF Valuation) recalculate LIVE from that selection -- every number is a real Excel formula traceable back to Sheet 6's input cells.
B13: 3. Yellow-filled cells are editable inputs (assumptions). White cells are formulas -- do not overtype them, or traceability is lost.
B14: 4. Sheets 3-5, 12-15 are reference/appendix data (historical facts, sensitivity dry-runs, source lineage, validation results, limitations) -- static, regenerated by the project's Python pipeline, not live Excel formulas.
B15: 5. A static 'All-Scenario Comparison' table appears below the live forecast on Sheets 7 and 11 for side-by-side reference across all 3 scenarios at once.
B17: Sheet index
B18: 1. Cover & Instructions
B19: 2. Executive Summary
B20: 3. Historical Financials
... B32: 15. Limitations

Sheet Executive Summary
A1: Executive Summary
A2: Scenario-based model. NOT investment advice, a price target, or a prediction. See Sheet 15 for limitations.
A4: Metric (FY2030 unless noted) | B4: Base | C4: Upside | D4: Downside
A5: Revenue ($M) | B5: 110124.83 | C5: 121468.74 | D5: 92321.21
A6: Net Income ($M) | B6: 3636.58 | C6: 5556.31 | D6: 1234.99
A7: Diluted EPS ($) | B7: 8.18 | C7: 13.15 | D7: 2.71
A8: CFO ($M) | B8: 7765.83 | C8: 10263.59 | D8: 4667.64
A9: FCF ($M) | B9: 3801.34 | C9: 5040.43 | D9: 2082.64
A11: Corrected Capacity Taxonomy (FY2030) -- see Sheet 9 for full detail
A12: Opening Excess Liquidity ($M, a STOCK -- never 'generated') | B12: 5424.25 | C12: 2217.5 | D12: 6157.88
A13: Self-Funded Capacity Generated ($M) | B13: 1590.77 | C13: 2024.44 | D13: 29.64
A14: Debt-Funded Capacity ($M, net of repayment) | B14: 0 | C14: 0 | D14: 200
A15: Discretionary Deployment ($M) | B15: 636.31 | C15: 1498.44 | D15: 0
A16: Remaining Deployable Headroom ($M) | B16: 6378.71 | C16: 2043.5 | D16: 6387.52
A18: Note: a higher-revenue scenario can show LOWER remaining headroom -- it may be deploying far more into buybacks/deleveraging (Upside), not generating less. See the FY2030 scenario bridges in docs/investment_capacity_correction_evidence.md and Sheet 9.
A19: Implied DCF Value/Share ($) | B19: 107.29 | C19: 138.32 | D19: 61.55
A21: Key question answered:
A22: How much capital can Target safely deploy after funding operations, CapEx, dividends, minimum liquidity, and debt obligations? -- see Sheet 9 (Investment Capacity) for the full FY2026-FY2030 build for the selected scenario.
A24: Scenario | B24: Remaining Deployable Headroom, FY2030 ($M)
A25: Base | B25: 6378.7
A26: Upside | B26: 2043.5
A27: Downside | B27: 6387.5

Sheet Historical Financials
A1: Historical Financials, FY2021-FY2025 (latest_restated, ACTUAL)
A3: Line Item | B3: FY2021 | C3: FY2022 | D3: FY2023 | E3: FY2024 | F3: FY2025
A4: Revenue | B4: 106005 | C4: 109120 | D4: 107412 | E4: 106566 | F4: 104780
A5: Cost of Sales | B5: 74963 | C5: 82306 | D5: 77828 | E5: 76502 | F5: 75511
A6: Gross Profit | B6: 31042 | C6: 26814 | D6: 29584 | E6: 30064 | F6: 29269
A7: SG&A | B7: 19752 | C7: 20581 | D7: 21462 | E7: 21969 | F7: 21535
A8: D&A (Opex) | B8: 2344 | C8: 2385 | D8: 2415 | E8: 2529 | F8: 2617
A9: Operating Income | B9: 8946 | C9: 3848 | D9: 5707 | E9: 5566 | F9: 5117
A10: Interest Expense | B10: 421 | C10: 478 | D10: 502 | E10: 411 | F10: 445
A11: Net Other Income | B11: 382 | C11: 48 | D11: 92 | E11: 106 | F11: 95
A12: Pretax Income | B12: 8907 | C12: 3418 | D12: 5297 | E12: 5261 | F12: 4767
A13: Income Tax Expense | B13: 1961 | C13: 638 | D13: 1159 | E13: 1170 | F13: 1062
A14: Net Income | B14: 6946 | C14: 2780 | D14: 4138 | E14: 4091 | F14: 3705
A15: Diluted EPS ($) | B15: 14.1 | C15: 5.98 | D15: 8.94 | E15: 8.86 | F15: 8.13
... A25: Total Debt (GAAP, excl. finance leases) | B25: 11645 | C25: 14067 | D25: 14025 | E25: 13779 | F25: 14343
A27: Note: FY2023 was a 53-week fiscal year. All figures are the LATEST-RESTATED analytical view -- see Sheet 4 for the as-originally-filed vs. restated comparison.

Sheet Filing-Vintage Comparison
A1: Filing-Vintage Comparison: As-Originally-Filed vs. Latest-Restated
A2: Target reclassified certain distribution-center costs between Cost of Sales and SG&A in later filings (disclosed reclassification, FY2022-FY2023 restated views differ from the originally-filed views). Revenue is identical in both views every year -- only the COGS/SG&A split moved.
A4: Metric | B4: FY | C4: As-Originally-Filed | D4: Latest-Restated | E4: Difference | F4: % Change | G4: Reclassified?
A5: Revenue | B5: 2021 | C5: 106005 | D5: 106005 | E5: 0 | F5: 0 | G5: no
A6: Revenue | B6: 2022 | C6: 109120 | D6: 109120 | E6: 0 | F6: 0 | G6: no
A7: Revenue | B7: 2023 | C7: 107412 | D7: 107412 | E7: 0 | F7: 0 | G7: no
A8: Revenue | B8: 2024 | C8: 106566 | D8: 106566 | E8: 0 | F8: 0 | G8: no
A9: Revenue | B9: 2025 | C9: 104780 | D9: 104780 | E9: 0 | F9: 0 | G9: no
A10: Cost of Sales | B10: 2021 | C10: 74963 | D10: 74963 | E10: 0 | F10: 0 | G10: no
A11: Cost of Sales | B11: 2022 | C11: 82229 | D11: 82306 | E11: 77 | F11: 0.0009364093 | G11: YES
A12: Cost of Sales | B12: 2023 | C12: 77736 | D12: 77828 | E12: 92 | F12: 0.0011834928 | G12: YES
A13: Cost of Sales | B13: 2024 | C13: 76502 | D13: 76502 | E13: 0 | F13: 0 | G13: no
A14: Cost of Sales | B14: 2025 | C14: 75511 | D14: 75511 | E14: 0 | F14: 0 | G14: no
A15: Gross Profit | B15: 2021 | C15: 31042 | D15: 31042 | E15: 0 | F15: 0 | G15: no
A16: Gross Profit | B16: 2022 | C16: 26891 | D16: 26814 | E16: -77 | F16: -0.0028634116 | G16: YES
... A24: SG&A | B24: 2025 | C24: 21535 | D24: 21535 | E24: 0 | F24: 0 | G24: no

Sheet Quarterly Cash Proof
A1: Quarterly Cash Proof -- FY2025 Seasonality Evidence
A2: The only year of quarterly granularity in the registered source set. Grounds the seasonal-liquidity-stress overlay's 50% haircut (Q1 trough vs. Q4/year-end = 52.6%).
A4: As-Of Date | B4: Cash & Equivalents ($M) | C4: Accession | D4: Period
A5: 2025-02-01 | B5: 4762 | C5: 0000027419-25-000018 | D5: FY2024 Year-End
A6: 2025-05-03 | B6: 2887 | C6: 0000027419-25-000101 | D6: FY2025 Q1 (trough)
A7: 2025-08-02 | B7: 4341 | C7: 0000027419-25-000118 | D7: FY2025 Q2
A8: 2025-11-01 | B8: 3822 | C8: 0000027419-25-000126 | D8: FY2025 Q3
A9: 2026-01-31 | B9: 5488 | C9: 0000027419-26-000016 | D9: FY2025 Q4/Year-End
A11: Trough / Year-End Ratio | B11: 0.52605685

Sheet Forecast Assumptions
A1: Forecast Assumptions (FY2026-FY2030)
A2: Scenario Selector | C2: Base | D2: <- choose Base / Upside / Downside; drives Sheets 7-11 live
A4: Assumption | B4: Area | C4: Unit | D4: Base FY2026 | E4: Base FY2027 | F4: Base FY2028 | G4: Base FY2029 | H4: Base FY2030 | J4: Upside FY2026 | K4: Upside FY2027 | L4: Upside FY2028 | M4: Upside FY2029 | N4: Upside FY2030 | P4: Downside FY2026 | Q4: Downside FY2027 | R4: Downside FY2028 | S4: Downside FY2029 | T4: Downside FY2030
A5: Revenue growth %/yr | B5: Revenue | C5: % | D5: 0.01 | E5: 0.01 | F5: 0.01 | G5: 0.01 | H5: 0.01 | J5: 0.03 | K5: 0.03 | L5: 0.03 | M5: 0.03 | N5: 0.03 | P5: -0.025 | Q5: -0.025 | R5: -0.025 | S5: -0.025 | T5: -0.025
A6: Gross margin % | B6: Gross Profit | C6: % | D6: 0.2793 | E6: 0.27947 | F6: 0.27965 | G6: 0.27983 | H6: 0.28 | J6: 0.2793 | K6: 0.28148 | L6: 0.28365 | M6: 0.28582 | N6: 0.288 | P6: 0.2793 | Q6: 0.27523 | R6: 0.27115 | S6: 0.26707 | T6: 0.263
A7: SG&A % of revenue | B7: Operating Expenses | C7: % | D7: 0.2055 | E7: 0.2055 | F7: 0.2055 | G7: 0.2055 | H7: 0.2055 | J7: 0.2055 | K7: 0.20363 | L7: 0.20175 | M7: 0.19988 | N7: 0.198 | P7: 0.2055 | Q7: 0.20738 | R7: 0.20925 | S7: 0.21113 | T7: 0.213
A8: D&A in opex, % of revenue | B8: Operating Expenses | C8: % | D8: 0.02578 | E8: 0.02655 | F8: 0.02732 | G8: 0.0281 | H8: 0.02888 | J8: 0.02678 | K8: 0.02755 | L8: 0.02833 | M8: 0.0291 | N8: 0.02988 | P8: 0.02478 | Q8: 0.02555 | R8: 0.02632 | S8: 0.0271 | T8: 0.02788
A9: Effective tax rate % | B9: Income Tax | C9: % | D9: 0.222 | E9: 0.222 | F9: 0.222 | G9: 0.222 | H9: 0.222 | J9: 0.215 | K9: 0.215 | L9: 0.215 | M9: 0.215 | N9: 0.215 | P9: 0.23 | Q9: 0.23 | R9: 0.23 | S9: 0.23 | T9: 0.23
A10: Net other income ($M) | B10: Other Income | C10: $M | D10: 95 | E10: 95 | F10: 95 | G10: 95 | H10: 95 | J10: 100 | K10: 100 | L10: 100 | M10: 100 | N10: 100 | P10: 80 | Q10: 80 | R10: 80 | S10: 80 | T10: 80
A11: Diluted share count change %/yr | B11: Shares | C11: % | D11: -0.005 | E11: -0.005 | F11: -0.005 | G11: -0.005 | H11: -0.005 | J11: -0.015 | K11: -0.015 | L11: -0.015 | M11: -0.015 | N11: -0.015 | P11: 0 | Q11: 0 | R11: 0 | S11: 0 | T11: 0
A12: Interest rate on avg debt % | B12: Interest | C12: % | D12: 0.031 | E12: 0.031 | F12: 0.031 | G12: 0.031 | H12: 0.031 | J12: 0.029 | K12: 0.029 | L12: 0.029 | M12: 0.029 | N12: 0.029 | P12: 0.034 | Q12: 0.034 | R12: 0.034 | S12: 0.034 | T12: 0.034
A13: CapEx % of revenue | B13: CapEx | C13: % | D13: 0.036 | E13: 0.036 | F13: 0.036 | G13: 0.036 | H13: 0.036 | J13: 0.043 | K13: 0.043 | L13: 0.043 | M13: 0.043 | N13: 0.043 | P13: 0.028 | Q13: 0.028 | R13: 0.028 | S13: 0.028 | T13: 0.028
A14: D&A CFO add-back % of revenue | B14: Cash Flow | C14: % | D14: 0.03116 | E14: 0.0324 | F14: 0.03365 | G14: 0.0349 | H14: 0.03614 | J14: 0.03166 | K14: 0.0329 | L14: 0.03415 | M14: 0.0354 | N14: 0.03664 | P14: 0.03066 | Q14: 0.0319 | R14: 0.03315 | S14: 0.0344 | T14: 0.03564
A15: Inventory % of revenue | B15: Working Capital | C15: % | D15: 0.118 | E15: 0.118 | F15: 0.118 | G15: 0.118 | H15: 0.118 | J15: 0.11 | K15: 0.11 | L15: 0.11 | M15: 0.11 | N15: 0.11 | P15: 0.128 | Q15: 0.128 | R15: 0.128 | S15: 0.128 | T15: 0.128
A16: Accounts payable % of COGS | B16: Working Capital | C16: % | D16: 0.167 | E16: 0.167 | F16: 0.167 | G16: 0.167 | H16: 0.167 | J16: 0.175 | K16: 0.175 | L16: 0.175 | M16: 0.175 | N16: 0.175 | P16: 0.155 | Q16: 0.155 | R16: 0.155 | S16: 0.155 | T16: 0.155
... A23: Minimum cash buffer % of revenue | B23: Liquidity Policy | C23: % | D23: 0.03 | E23: 0.03 | F23: 0.03 | G23: 0.03 | H23: 0.03 | J23: 0.03 | K23: 0.03 | L23: 0.03 | M23: 0.03 | N23: 0.03 | P23: 0.03 | Q23: 0.03 | R23: 0.03 | S23: 0.03 | T23: 0.03

Sheet Scenario Forecast
A1: Scenario Forecast -- Income Statement (LIVE, driven by Sheet 6 selector)
A2: Selected scenario: | B2: ='Forecast Assumptions'!$C$2
A4: Line Item | D4: FY2026 | E4: FY2027 | F4: FY2028 | G4: FY2029 | H4: FY2030
A5: Revenue | D5: =104780.0*(1+(IF('Forecast Assumptions'!$C$2="Base",'Forecast Assumptions'!D5,IF('Forecast Assumptions'!$C$2="Upside",'Forecast Assumptions'!J5,'Forecast Assumptions'!P5)))) | E5: =D5*(1+(IF('Forecast Assumptions'!$C$2="Base",'Forecast Assumptions'!E5,IF('Forecast Assumptions'!$C$2="Upside",'Forecast Assumptions'!K5,'Forecast Assumptions'!Q5)))) | F5: =E5*(1+(IF('Forecast Assumptions'!$C$2="Base",'Forecast Assumptions'!F5,IF('Forecast Assumptions'!$C$2="Upside",'Forecast Assumptions'!L5,'Forecast Assumptions'!R5)))) | G5: =F5*(1+(IF('Forecast Assumptions'!$C$2="Base",'Forecast Assumptions'!G5,IF('Forecast Assumptions'!$C$2="Upside",'Forecast Assumptions'!M5,'Forecast Assumptions'!S5)))) | H5: =G5*(1+(IF('Forecast Assumptions'!$C$2="Base",'Forecast Assumptions'!H5,IF('Forecast Assumptions'!$C$2="Upside",'Forecast Assumptions'!N5,'Forecast Assumptions'!T5))))
A6: Cost of Sales | D6: =D5-D7 | E6: =E5-E7 | F6: =F5-F7 | G6: =G5-G7 | H6: =H5-H7
A7: Gross Profit | D7: =D5*D8 | E7: =E5*E8 | F7: =F5*F8 | G7: =G5*G8 | H7: =H5*H8
A8: Gross Margin % | D8: =IF('Forecast Assumptions'!$C$2="Base",'Forecast Assumptions'!D6,IF('Forecast Assumptions'!$C$2="Upside",'Forecast Assumptions'!J6,'Forecast Assumptions'!P6)) | E8: =IF('Forecast Assumptions'!$C$2="Base",'Forecast Assumptions'!E6,IF('Forecast Assumptions'!$C$2="Upside",'Forecast Assumptions'!K6,'Forecast Assumptions'!Q6)) | F8: =IF('Forecast Assumptions'!$C$2="Base",'Forecast Assumptions'!F6,IF('Forecast Assumptions'!$C$2="Upside",'Forecast Assumptions'!L6,'Forecast Assumptions'!R6)) | G8: =IF('Forecast Assumptions'!$C$2="Base",'Forecast Assumptions'!G6,IF('Forecast Assumptions'!$C$2="Upside",'Forecast Assumptions'!M6,'Forecast Assumptions'!S6)) | H8: =IF('Forecast Assumptions'!$C$2="Base",'Forecast Assumptions'!H6,IF('Forecast Assumptions'!$C$2="Upside",'Forecast Assumptions'!N6,'Forecast Assumptions'!T6))
A9: SG&A | D9: =D5*(IF('Forecast Assumptions'!$C$2="Base",'Forecast Assumptions'!D7,IF('Forecast Assumptions'!$C$2="Upside",'Forecast Assumptions'!J7,'Forecast Assumptions'!P7))) | E9: =E5*(IF('Forecast Assumptions'!$C$2="Base",'Forecast Assumptions'!E7,IF('Forecast Assumptions'!$C$2="Upside",'Forecast Assumptions'!K7,'Forecast Assumptions'!Q7))) | F9: =F5*(IF('Forecast Assumptions'!$C$2="Base",'Forecast Assumptions'!F7,IF('Forecast Assumptions'!$C$2="Upside",'Forecast Assumptions'!L7,'Forecast Assumptions'!R7))) | G9: =G5*(IF('Forecast Assumptions'!$C$2="Base",'Forecast Assumptions'!G7,IF('Forecast Assumptions'!$C$2="Upside",'Forecast Assumptions'!M7,'Forecast Assumptions'!S7))) | H9: =H5*(IF('Forecast Assumptions'!$C$2="Base",'Forecast Assumptions'!H7,IF('Forecast Assumptions'!$C$2="Upside",'Forecast Assumptions'!N7,'Forecast Assumptions'!T7)))
A10: D&A (in Opex) | D10: =D5*(IF('Forecast Assumptions'!$C$2="Base",'Forecast Assumptions'!D8,IF('Forecast Assumptions'!$C$2="Upside",'Forecast Assumptions'!J8,'Forecast Assumptions'!P8))) | E10: =E5*(IF('Forecast Assumptions'!$C$2="Base",'Forecast Assumptions'!E8,IF('Forecast Assumptions'!$C$2="Upside",'Forecast Assumptions'!K8,'Forecast Assumptions'!Q8))) | F10: =F5*(IF('Forecast Assumptions'!$C$2="Base",'Forecast Assumptions'!F8,IF('Forecast Assumptions'!$C$2="Upside",'Forecast Assumptions'!L8,'Forecast Assumptions'!R8))) | G10: =G5*(IF('Forecast Assumptions'!$C$2="Base",'Forecast Assumptions'!G8,IF('Forecast Assumptions'!$C$2="Upside",'Forecast Assumptions'!M8,'Forecast Assumptions'!S8))) | H10: =H5*(IF('Forecast Assumptions'!$C$2="Base",'Forecast Assumptions'!H8,IF('Forecast Assumptions'!$C$2="Upside",'Forecast Assumptions'!N8,'Forecast Assumptions'!T8)))
A11: Operating Income | D11: =D7-D9-D10 | E11: =E7-E9-E10 | F11: =F7-F9-F10 | G11: =G7-G9-G10 | H11: =H7-H9-H10
A12: Operating Margin % | D12: =D11/D5 | E12: =E11/E5 | F12: =F11/F5 | G12: =G11/G5 | H12: =H11/H5
A13: Total Debt, Beginning | D13: =14343.0 | E13: =D14 | F13: =E14 | G13: =F14 | H13: =G14
A14: Total Debt, Ending | D14: =D13+(IF('Forecast Assumptions'!$C$2="Base",'Forecast Assumptions'!D20,IF('Forecast Assumptions'!$C$2="Upside",'Forecast Assumptions'!J20,'Forecast Assumptions'!P20)))-(IF('Forecast Assumptions'!$C$2="Base",'Forecast Assumptions'!D21,IF('Forecast Assumptions'!$C$2="Upside",'Forecast Assumptions'!J21,'Forecast Assumptions'!P21))) | E14: =E13+(IF('Forecast Assumptions'!$C$2="Base",'Forecast Assumptions'!E20,IF('Forecast Assumptions'!$C$2="Upside",'Forecast Assumptions'!K20,'Forecast Assumptions'!Q20)))-(IF('Forecast Assumptions'!$C$2="Base",'Forecast Assumptions'!E21,IF('Forecast Assumptions'!$C$2="Upside",'Forecast Assumptions'!K21,'Forecast Assumptions'!Q21))) | F14: =F13+(IF('Forecast Assumptions'!$C$2="Base",'Forecast Assumptions'!F20,IF('Forecast Assumptions'!$C$2="Upside",'Forecast Assumptions'!L20,'Forecast Assumptions'!R20)))-(IF('Forecast Assumptions'!$C$2="Base",'Forecast Assumptions'!F21,IF('Forecast Assumptions'!$C$2="Upside",'Forecast Assumptions'!L21,'Forecast Assumptions'!R21))) | G14: =G13+(IF('Forecast Assumptions'!$C$2="Base",'Forecast Assumptions'!G20,IF('Forecast Assumptions'!$C$2="Upside",'Forecast Assumptions'!M20,'Forecast Assumptions'!S20)))-(IF('Forecast Assumptions'!$C$2="Base",'Forecast Assumptions'!G21,IF('Forecast Assumptions'!$C$2="Upside",'Forecast Assumptions'!M21,'Forecast Assumptions'!S21))) | H14: =H13+(IF('Forecast Assumptions'!$C$2="Base",'Forecast Assumptions'!H20,IF('Forecast Assumptions'!$C$2="Upside",'Forecast Assumptions'!N20,'Forecast Assumptions'!T20)))-(IF('Forecast Assumptions'!$C$2="Base",'Forecast Assumptions'!H21,IF('Forecast Assumptions'!$C$2="Upside",'Forecast Assumptions'!N21,'Forecast Assumptions'!T21)))
A15: Interest Expense | D15: =(IF('Forecast Assumptions'!$C$2="Base",'Forecast Assumptions'!D12,IF('Forecast Assumptions'!$C$2="Upside",'Forecast Assumptions'!J12,'Forecast Assumptions'!P12)))*AVERAGE(D13,D14) | E15: =(IF('Forecast Assumptions'!$C$2="Base",'Forecast Assumptions'!E12,IF('Forecast Assumptions'!$C$2="Upside",'Forecast Assumptions'!K12,'Forecast Assumptions'!Q12)))*AVERAGE(E13,E14) | F15: =(IF('Forecast Assumptions'!$C$2="Base",'Forecast Assumptions'!F12,IF('Forecast Assumptions'!$C$2="Upside",'Forecast Assumptions'!L12,'Forecast Assumptions'!R12)))*AVERAGE(F13,F14) | G15: =(IF('Forecast Assumptions'!$C$2="Base",'Forecast Assumptions'!G12,IF('Forecast Assumptions'!$C$2="Upside",'Forecast Assumptions'!M12,'Forecast Assumptions'!S12)))*AVERAGE(G13,G14) | H15: =(IF('Forecast Assumptions'!$C$2="Base",'Forecast Assumptions'!H12,IF('Forecast Assumptions'!$C$2="Upside",'Forecast Assumptions'!N12,'Forecast Assumptions'!T12)))*AVERAGE(H13,H14)
A16: Net Other Income | D16: =IF('Forecast Assumptions'!$C$2="Base",'Forecast Assumptions'!D10,IF('Forecast Assumptions'!$C$2="Upside",'Forecast Assumptions'!J10,'Forecast Assumptions'!P10)) | E16: =IF('Forecast Assumptions'!$C$2="Base",'Forecast Assumptions'!E10,IF('Forecast Assumptions'!$C$2="Upside",'Forecast Assumptions'!K10,'Forecast Assumptions'!Q10)) | F16: =IF('Forecast Assumptions'!$C$2="Base",'Forecast Assumptions'!F10,IF('Forecast Assumptions'!$C$2="Upside",'Forecast Assumptions'!L10,'Forecast Assumptions'!R10)) | G16: =IF('Forecast Assumptions'!$C$2="Base",'Forecast Assumptions'!G10,IF('Forecast Assumptions'!$C$2="Upside",'Forecast Assumptions'!M10,'Forecast Assumptions'!S10)) | H16: =IF('Forecast Assumptions'!$C$2="Base",'Forecast Assumptions'!H10,IF('Forecast Assumptions'!$C$2="Upside",'Forecast Assumptions'!N10,'Forecast Assumptions'!T10))
A17: Pretax Income | D17: =D11-D15+D16 | E17: =E11-E15+E16 | F17: =F11-F15+F16 | G17: =G11-G15+G16 | H17: =H11-H15+H16
A18: Income Tax Expense | D18: =D17*(IF('Forecast Assumptions'!$C$2="Base",'Forecast Assumptions'!D9,IF('Forecast Assumptions'!$C$2="Upside",'Forecast Assumptions'!J9,'Forecast Assumptions'!P9))) | E18: =E17*(IF('Forecast Assumptions'!$C$2="Base",'Forecast Assumptions'!E9,IF('Forecast Assumptions'!$C$2="Upside",'Forecast Assumptions'!K9,'Forecast Assumptions'!Q9))) | F18: =F17*(IF('Forecast Assumptions'!$C$2="Base",'Forecast Assumptions'!F9,IF('Forecast Assumptions'!$C$2="Upside",'Forecast Assumptions'!L9,'Forecast Assumptions'!R9))) | G18: =G17*(IF('Forecast Assumptions'!$C$2="Base",'Forecast Assumptions'!G9,IF('Forecast Assumptions'!$C$2="Upside",'Forecast Assumptions'!M9,'Forecast Assumptions'!S9))) | H18: =H17*(IF('Forecast Assumptions'!$C$2="Base",'Forecast Assumptions'!H9,IF('Forecast Assumptions'!$C$2="Upside",'Forecast Assumptions'!N9,'Forecast Assumptions'!T9)))
A19: Net Income | D19: =D17-D18 | E19: =E17-E18 | F19: =F17-F18 | G19: =G17-G18 | H19: =H17-H18
A20: Diluted Shares (M) | D20: =455.6*(1+(IF('Forecast Assumptions'!$C$2="Base",'Forecast Assumptions'!D11,IF('Forecast Assumptions'!$C$2="Upside",'Forecast Assumptions'!J11,'Forecast Assumptions'!P11)))) | E20: =D20*(1+(IF('Forecast Assumptions'!$C$2="Base",'Forecast Assumptions'!E11,IF('Forecast Assumptions'!$C$2="Upside",'Forecast Assumptions'!K11,'Forecast Assumptions'!Q11)))) | F20: =E20*(1+(IF('Forecast Assumptions'!$C$2="Base",'Forecast Assumptions'!F11,IF('Forecast Assumptions'!$C$2="Upside",'Forecast Assumptions'!L11,'Forecast Assumptions'!R11)))) | G20: =F20*(1+(IF('Forecast Assumptions'!$C$2="Base",'Forecast Assumptions'!G11,IF('Forecast Assumptions'!$C$2="Upside",'Forecast Assumptions'!M11,'Forecast Assumptions'!S11)))) | H20: =G20*(1+(IF('Forecast Assumptions'!$C$2="Base",'Forecast Assumptions'!H11,IF('Forecast Assumptions'!$C$2="Upside",'Forecast Assumptions'!N11,'Forecast Assumptions'!T11))))
A21: Diluted EPS ($) | D21: =D19/D20 | E21: =E19/E20 | F21: =F19/F20 | G21: =G19/G20 | H21: =H19/H20

Sheet Cash-Flow Bridge
A1: Cash-Flow Bridge (LIVE, driven by Sheet 6 selector)
A2: Selected scenario: | B2: ='Forecast Assumptions'!$C$2
A4: Line Item | D4: FY2026 | E4: FY2027 | F4: FY2028 | G4: FY2029 | H4: FY2030
A5: Inventory Balance | D5: ='Scenario Forecast'!D5*(IF('Forecast Assumptions'!$C$2="Base",'Forecast Assumptions'!D15,IF('Forecast Assumptions'!$C$2="Upside",'Forecast Assumptions'!J15,'Forecast Assumptions'!P15))) | E5: ='Scenario Forecast'!E5*(IF('Forecast Assumptions'!$C$2="Base",'Forecast Assumptions'!E15,IF('Forecast Assumptions'!$C$2="Upside",'Forecast Assumptions'!K15,'Forecast Assumptions'!Q15))) | F5: ='Scenario Forecast'!F5*(IF('Forecast Assumptions'!$C$2="Base",'Forecast Assumptions'!F15,IF('Forecast Assumptions'!$C$2="Upside",'Forecast Assumptions'!L15,'Forecast Assumptions'!R15))) | G5: ='Scenario Forecast'!G5*(IF('Forecast Assumptions'!$C$2="Base",'Forecast Assumptions'!G15,IF('Forecast Assumptions'!$C$2="Upside",'Forecast Assumptions'!M15,'Forecast Assumptions'!S15))) | H5: ='Scenario Forecast'!H5*(IF('Forecast Assumptions'!$C$2="Base",'Forecast Assumptions'!H15,IF('Forecast Assumptions'!$C$2="Upside",'Forecast Assumptions'!N15,'Forecast Assumptions'!T15)))
A6: Inventory Cash Impact | D6: =-(D5-12304.0) | E6: =-(E5-D5) | F6: =-(F5-E5) | G6: =-(G5-F5) | H6: =-(H5-G5)
A7: Accounts Payable Balance | D7: ='Scenario Forecast'!D6*(IF('Forecast Assumptions'!$C$2="Base",'Forecast Assumptions'!D16,IF('Forecast Assumptions'!$C$2="Upside",'Forecast Assumptions'!J16,'Forecast Assumptions'!P16))) | E7: ='Scenario Forecast'!E6*(IF('Forecast Assumptions'!$C$2="Base",'Forecast Assumptions'!E16,IF('Forecast Assumptions'!$C$2="Upside",'Forecast Assumptions'!K16,'Forecast Assumptions'!Q16))) | F7: ='Scenario Forecast'!F6*(IF('Forecast Assumptions'!$C$2="Base",'Forecast Assumptions'!F16,IF('Forecast Assumptions'!$C$2="Upside",'Forecast Assumptions'!L16,'Forecast Assumptions'!R16))) | G7: ='Scenario Forecast'!G6*(IF('Forecast Assumptions'!$C$2="Base",'Forecast Assumptions'!G16,IF('Forecast Assumptions'!$C$2="Upside",'Forecast Assumptions'!M16,'Forecast Assumptions'!S16))) | H7: ='Scenario Forecast'!H6*(IF('Forecast Assumptions'!$C$2="Base",'Forecast Assumptions'!H16,IF('Forecast Assumptions'!$C$2="Upside",'Forecast Assumptions'!N16,'Forecast Assumptions'!T16)))
A8: AP Cash Impact | D8: =D7-12622.0 | E8: =E7-D7 | F8: =F7-E7 | G8: =G7-F7 | H8: =H7-G7
A9: D&A Cash-Flow Add-back | D9: ='Scenario Forecast'!D5*(IF('Forecast Assumptions'!$C$2="Base",'Forecast Assumptions'!D14,IF('Forecast Assumptions'!$C$2="Upside",'Forecast Assumptions'!J14,'Forecast Assumptions'!P14))) | E9: ='Scenario Forecast'!E5*(IF('Forecast Assumptions'!$C$2="Base",'Forecast Assumptions'!E14,IF('Forecast Assumptions'!$C$2="Upside",'Forecast Assumptions'!K14,'Forecast Assumptions'!Q14))) | F9: ='Scenario Forecast'!F5*(IF('Forecast Assumptions'!$C$2="Base",'Forecast Assumptions'!F14,IF('Forecast Assumptions'!$C$2="Upside",'Forecast Assumptions'!L14,'Forecast Assumptions'!R14))) | G9: ='Scenario Forecast'!G5*(IF('Forecast Assumptions'!$C$2="Base",'Forecast Assumptions'!G14,IF('Forecast Assumptions'!$C$2="Upside",'Forecast Assumptions'!M14,'Forecast Assumptions'!S14))) | H9: ='Scenario Forecast'!H5*(IF('Forecast Assumptions'!$C$2="Base",'Forecast Assumptions'!H14,IF('Forecast Assumptions'!$C$2="Upside",'Forecast Assumptions'!N14,'Forecast Assumptions'!T14)))
A10: Other Operating Cash Adjustments | D10: =IF('Forecast Assumptions'!$C$2="Base",'Forecast Assumptions'!D17,IF('Forecast Assumptions'!$C$2="Upside",'Forecast Assumptions'!J17,'Forecast Assumptions'!P17)) | E10: =IF('Forecast Assumptions'!$C$2="Base",'Forecast Assumptions'!E17,IF('Forecast Assumptions'!$C$2="Upside",'Forecast Assumptions'!K17,'Forecast Assumptions'!Q17)) | F10: =IF('Forecast Assumptions'!$C$2="Base",'Forecast Assumptions'!F17,IF('Forecast Assumptions'!$C$2="Upside",'Forecast Assumptions'!L17,'Forecast Assumptions'!R17)) | G10: =IF('Forecast Assumptions'!$C$2="Base",'Forecast Assumptions'!G17,IF('Forecast Assumptions'!$C$2="Upside",'Forecast Assumptions'!M17,'Forecast Assumptions'!S17)) | H10: =IF('Forecast Assumptions'!$C$2="Base",'Forecast Assumptions'!H17,IF('Forecast Assumptions'!$C$2="Upside",'Forecast Assumptions'!N17,'Forecast Assumptions'!T17))
A11: Cash Flow from Operations (CFO) | D11: ='Scenario Forecast'!D19+D9+D6+D8+D10 | E11: ='Scenario Forecast'!E19+E9+E6+E8+E10 | F11: ='Scenario Forecast'!F19+F9+F6+F8+F10 | G11: ='Scenario Forecast'!G19+G9+G6+G8+G10 | H11: ='Scenario Forecast'!H19+H9+H6+H8+H10
A12: Capital Expenditures (CapEx) | D12: ='Scenario Forecast'!D5*(IF('Forecast Assumptions'!$C$2="Base",'Forecast Assumptions'!D13,IF('Forecast Assumptions'!$C$2="Upside",'Forecast Assumptions'!J13,'Forecast Assumptions'!P13))) | E12: ='Scenario Forecast'!E5*(IF('Forecast Assumptions'!$C$2="Base",'Forecast Assumptions'!E13,IF('Forecast Assumptions'!$C$2="Upside",'Forecast Assumptions'!K13,'Forecast Assumptions'!Q13))) | F12: ='Scenario Forecast'!F5*(IF('Forecast Assumptions'!$C$2="Base",'Forecast Assumptions'!F13,IF('Forecast Assumptions'!$C$2="Upside",'Forecast Assumptions'!L13,'Forecast Assumptions'!R13))) | G12: ='Scenario Forecast'!G5*(IF('Forecast Assumptions'!$C$2="Base",'Forecast Assumptions'!G13,IF('Forecast Assumptions'!$C$2="Upside",'Forecast Assumptions'!M13,'Forecast Assumptions'!S13))) | H12: ='Scenario Forecast'!H5*(IF('Forecast Assumptions'!$C$2="Base",'Forecast Assumptions'!H13,IF('Forecast Assumptions'!$C$2="Upside",'Forecast Assumptions'!N13,'Forecast Assumptions'!T13)))
A13: Free Cash Flow (CFO - CapEx) | D13: =D11-D12 | E13: =E11-E12 | F13: =F11-F12 | G13: =G11-G12 | H13: =H11-H12
A14: Total Investing Cash Flow (=-CapEx here) | D14: =-D12 | E14: =-E12 | F14: =-F12 | G14: =-G12 | H14: =-H12
A15: Dividend per Share ($) | D15: =4.506145741878841*(1+(IF('Forecast Assumptions'!$C$2="Base",'Forecast Assumptions'!D18,IF('Forecast Assumptions'!$C$2="Upside",'Forecast Assumptions'!J18,'Forecast Assumptions'!P18)))) | E15: =D15*(1+(IF('Forecast Assumptions'!$C$2="Base",'Forecast Assumptions'!E18,IF('Forecast Assumptions'!$C$2="Upside",'Forecast Assumptions'!K18,'Forecast Assumptions'!Q18)))) | F15: =E15*(1+(IF('Forecast Assumptions'!$C$2="Base",'Forecast Assumptions'!F18,IF('Forecast Assumptions'!$C$2="Upside",'Forecast Assumptions'!L18,'Forecast Assumptions'!R18)))) | G15: =F15*(1+(IF('Forecast Assumptions'!$C$2="Base",'Forecast Assumptions'!G18,IF('Forecast Assumptions'!$C$2="Upside",'Forecast Assumptions'!M18,'Forecast Assumptions'!S18)))) | H15: =G15*(1+(IF('Forecast Assumptions'!$C$2="Base",'Forecast Assumptions'!H18,IF('Forecast Assumptions'!$C$2="Upside",'Forecast Assumptions'!N18,'Forecast Assumptions'!T18))))
A16: Dividends Paid | D16: =D15*'Scenario Forecast'!D20 | E16: =E15*'Scenario Forecast'!E20 | F16: =F15*'Scenario Forecast'!F20 | G16: =G15*'Scenario Forecast'!G20 | H16: =H15*'Scenario Forecast'!H20
A17: Post-Dividend FCF | D17: =D13-D16 | E17: =E13-E16 | F17: =F13-F16 | G17: =G13-G16 | H17: =H13-H16
A18: Share Repurchases | D18: =MAX(0,D17*(IF('Forecast Assumptions'!$C$2="Base",'Forecast Assumptions'!D19,IF('Forecast Assumptions'!$C$2="Upside",'Forecast Assumptions'!J19,'Forecast Assumptions'!P19)))) | E18: =MAX(0,E17*(IF('Forecast Assumptions'!$C$2="Base",'Forecast Assumptions'!E19,IF('Forecast Assumptions'!$C$2="Upside",'Forecast Assumptions'!K19,'Forecast Assumptions'!Q19)))) | F18: =MAX(0,F17*(IF('Forecast Assumptions'!$C$2="Base",'Forecast Assumptions'!F19,IF('Forecast Assumptions'!$C$2="Upside",'Forecast Assumptions'!L19,'Forecast Assumptions'!R19)))) | G18: =MAX(0,G17*(IF('Forecast Assumptions'!$C$2="Base",'Forecast Assumptions'!G19,IF('Forecast Assumptions'!$C$2="Upside",'Forecast Assumptions'!M19,'Forecast Assumptions'!S19)))) | H18: =MAX(0,H17*(IF('Forecast Assumptions'!$C$2="Base",'Forecast Assumptions'!H19,IF('Forecast Assumptions'!$C$2="Upside",'Forecast Assumptions'!N19,'Forecast Assumptions'!T19))))
A19: Debt Proceeds | D19: =IF('Forecast Assumptions'!$C$2="Base",'Forecast Assumptions'!D20,IF('Forecast Assumptions'!$C$2="Upside",'Forecast Assumptions'!J20,'Forecast Assumptions'!P20)) | E19: =IF('Forecast Assumptions'!$C$2="Base",'Forecast Assumptions'!E20,IF('Forecast Assumptions'!$C$2="Upside",'Forecast Assumptions'!K20,'Forecast Assumptions'!Q20)) | F19: =IF('Forecast Assumptions'!$C$2="Base",'Forecast Assumptions'!F20,IF('Forecast Assumptions'!$C$2="Upside",'Forecast Assumptions'!L20,'Forecast Assumptions'!R20)) | G19: =IF('Forecast Assumptions'!$C$2="Base",'Forecast Assumptions'!G20,IF('Forecast Assumptions'!$C$2="Upside",'Forecast Assumptions'!M20,'Forecast Assumptions'!S20)) | H19: =IF('Forecast Assumptions'!$C$2="Base",'Forecast Assumptions'!H20,IF('Forecast Assumptions'!$C$2="Upside",'Forecast Assumptions'!N20,'Forecast Assumptions'!T20))
A20: Debt Repayments | D20: =IF('Forecast Assumptions'!$C$2="Base",'Forecast Assumptions'!D21,IF('Forecast Assumptions'!$C$2="Upside",'Forecast Assumptions'!J21,'Forecast Assumptions'!P21)) | E20: =IF('Forecast Assumptions'!$C$2="Base",'Forecast Assumptions'!E21,IF('Forecast Assumptions'!$C$2="Upside",'Forecast Assumptions'!K21,'Forecast Assumptions'!Q21)) | F20: =IF('Forecast Assumptions'!$C$2="Base",'Forecast Assumptions'!F21,IF('Forecast Assumptions'!$C$2="Upside",'Forecast Assumptions'!L21,'Forecast Assumptions'!R21)) | G20: =IF('Forecast Assumptions'!$C$2="Base",'Forecast Assumptions'!G21,IF('Forecast Assumptions'!$C$2="Upside",'Forecast Assumptions'!M21,'Forecast Assumptions'!S21)) | H20: =IF('Forecast Assumptions'!$C$2="Base",'Forecast Assumptions'!H21,IF('Forecast Assumptions'!$C$2="Upside",'Forecast Assumptions'!N21,'Forecast Assumptions'!T21))
A21: Financing Cash Flow | D21: =-D16-D18+D19-D20 | E21: =-E16-E18+E19-E20 | F21: =-F16-F18+F19-F20 | G21: =-G16-G18+G19-G20 | H21: =-H16-H18+H19-H20
A22: Beginning Cash | D22: =5488.0 | E22: =D24 | F22: =E24 | G22: =F24 | H22: =G24
A23: Net Change in Cash | D23: =D11+D14+D21 | E23: =E11+E14+E21 | F23: =F11+F14+F21 | G23: =G11+G14+G21 | H23: =H11+H14+H21
A24: Ending Cash | D24: =D22+D23 | E24: =E22+E23 | F24: =F22+F23 | G24: =G22+G23 | H24: =H22+H23

Sheet Investment Capacity
A1: Investment Capacity (LIVE, driven by Sheet 6 selector)
A2: Selected scenario: | B2: ='Forecast Assumptions'!$C$2
A4: Line Item | D4: FY2026 | E4: FY2027 | F4: FY2028 | G4: FY2029 | H4: FY2030
A5: Gross FCF Capacity (=CFO-CapEx) | D5: ='Cash-Flow Bridge'!D13 | E5: ='Cash-Flow Bridge'!E13 | F5: ='Cash-Flow Bridge'!F13 | G5: ='Cash-Flow Bridge'!G13 | H5: ='Cash-Flow Bridge'!H13
A6: Post-Dividend Capacity | D6: ='Cash-Flow Bridge'!D13-'Cash-Flow Bridge'!D16 | E6: ='Cash-Flow Bridge'!E13-'Cash-Flow Bridge'!E16 | F6: ='Cash-Flow Bridge'!F13-'Cash-Flow Bridge'!F16 | G6: ='Cash-Flow Bridge'!G13-'Cash-Flow Bridge'!G16 | H6: ='Cash-Flow Bridge'!H13-'Cash-Flow Bridge'!H16
A7: Mandatory Financing Flows (div + debt sched.) | D7: =-'Cash-Flow Bridge'!D16+'Cash-Flow Bridge'!D19-'Cash-Flow Bridge'!D20 | E7: =-'Cash-Flow Bridge'!E16+'Cash-Flow Bridge'!E19-'Cash-Flow Bridge'!E20 | F7: =-'Cash-Flow Bridge'!F16+'Cash-Flow Bridge'!F19-'Cash-Flow Bridge'!F20 | G7: =-'Cash-Flow Bridge'!G16+'Cash-Flow Bridge'!G19-'Cash-Flow Bridge'!G20 | H7: =-'Cash-Flow Bridge'!H16+'Cash-Flow Bridge'!H19-'Cash-Flow Bridge'!H20
A8: Pre-Discretionary Ending Cash | D8: ='Cash-Flow Bridge'!D22+'Cash-Flow Bridge'!D11+'Cash-Flow Bridge'!D14+D7 | E8: ='Cash-Flow Bridge'!E22+'Cash-Flow Bridge'!E11+'Cash-Flow Bridge'!E14+E7 | F8: ='Cash-Flow Bridge'!F22+'Cash-Flow Bridge'!F11+'Cash-Flow Bridge'!F14+F7 | G8: ='Cash-Flow Bridge'!G22+'Cash-Flow Bridge'!G11+'Cash-Flow Bridge'!G14+G7 | H8: ='Cash-Flow Bridge'!H22+'Cash-Flow Bridge'!H11+'Cash-Flow Bridge'!H14+H7
A9: Minimum Cash Buffer | D9: ='Scenario Forecast'!D5*(IF('Forecast Assumptions'!$C$2="Base",'Forecast Assumptions'!D23,IF('Forecast Assumptions'!$C$2="Upside",'Forecast Assumptions'!J23,'Forecast Assumptions'!P23))) | E9: ='Scenario Forecast'!E5*(IF('Forecast Assumptions'!$C$2="Base",'Forecast Assumptions'!E23,IF('Forecast Assumptions'!$C$2="Upside",'Forecast Assumptions'!K23,'Forecast Assumptions'!Q23))) | F9: ='Scenario Forecast'!F5*(IF('Forecast Assumptions'!$C$2="Base",'Forecast Assumptions'!F23,IF('Forecast Assumptions'!$C$2="Upside",'Forecast Assumptions'!L23,'Forecast Assumptions'!R23))) | G9: ='Scenario Forecast'!G5*(IF('Forecast Assumptions'!$C$2="Base",'Forecast Assumptions'!G23,IF('Forecast Assumptions'!$C$2="Upside",'Forecast Assumptions'!M23,'Forecast Assumptions'!S23))) | H9: ='Scenario Forecast'!H5*(IF('Forecast Assumptions'!$C$2="Base",'Forecast Assumptions'!H23,IF('Forecast Assumptions'!$C$2="Upside",'Forecast Assumptions'!N23,'Forecast Assumptions'!T23)))
A10: Near-Term Debt Repayment Reserve | D10: ='Cash-Flow Bridge'!D20 | E10: ='Cash-Flow Bridge'!E20 | F10: ='Cash-Flow Bridge'!F20 | G10: ='Cash-Flow Bridge'!G20 | H10: ='Cash-Flow Bridge'!H20
A11: Legacy Gross Pre-Discretionary Ceiling (DEPRECATED -- see note below; not an executive KPI) | D11: =MAX(0,D8-D9-D10) | E11: =MAX(0,E8-E9-E10) | F11: =MAX(0,F8-F9-F10) | G11: =MAX(0,G8-G9-G10) | H11: =MAX(0,H8-H9-H10)
A12: Legacy Cumulative (DEPRECATED -- see Corrected Capacity Taxonomy below) | D12: ="see terminal year (FY2030)" | E12: ="see terminal year (FY2030)" | F12: ="see terminal year (FY2030)" | G12: ="see terminal year (FY2030)" | H12: =H11+0
A13: Funding Warning? (1=YES) | D13: =IF('Cash-Flow Bridge'!D24<D9,1,0) | E13: =IF('Cash-Flow Bridge'!E24<E9,1,0) | F13: =IF('Cash-Flow Bridge'!F24<F9,1,0) | G13: =IF('Cash-Flow Bridge'!G24<G9,1,0) | H13: =IF('Cash-Flow Bridge'!H24<H9,1,0)
A15: NOTE: the legacy row above is DEPRECATED -- it is a gross, pre-discretionary ceiling (includes carried-forward cash and new borrowing; never subtracts this year's own repurchases). It is preserved, unmodified, for backward compatibility only. The corrected taxonomy below is the executive-facing figure. See docs/investment_capacity_correction_evidence.md.
A17: CORRECTED CAPACITY TAXONOMY (live, selected scenario)
A18: Line Item | D18: FY2026 | E18: FY2027 | F18: FY2028 | G18: FY2029 | H18: FY2030
A19: A. Operating FCF (= CFO - CapEx) | D19: ='Cash-Flow Bridge'!D13 | E19: ='Cash-Flow Bridge'!E13 | F19: ='Cash-Flow Bridge'!F13 | G19: ='Cash-Flow Bridge'!G13 | H19: ='Cash-Flow Bridge'!H13
A20: B. Post-Dividend Internal Generation | D20: =D19-'Cash-Flow Bridge'!D16 | E20: =E19-'Cash-Flow Bridge'!E16 | F20: =F19-'Cash-Flow Bridge'!F16 | G20: =G19-'Cash-Flow Bridge'!G16 | H20: =H19-'Cash-Flow Bridge'!H16
A21: Opening Excess Liquidity (STOCK, = MAX(0, beg. cash - buffer)) -- never labeled 'generated' | D21: =MAX(0,'Cash-Flow Bridge'!D22-D9) | E21: =MAX(0,'Cash-Flow Bridge'!E22-E9) | F21: =MAX(0,'Cash-Flow Bridge'!F22-F9) | G21: =MAX(0,'Cash-Flow Bridge'!G22-G9) | H21: =MAX(0,'Cash-Flow Bridge'!H22-H9)
A22: Gross Debt Proceeds (supporting, transparent) | D22: ='Cash-Flow Bridge'!D19 | E22: ='Cash-Flow Bridge'!E19 | F22: ='Cash-Flow Bridge'!F19 | G22: ='Cash-Flow Bridge'!G19 | H22: ='Cash-Flow Bridge'!H19
A23: Gross Debt Repayments (supporting, transparent) | D23: ='Cash-Flow Bridge'!D20 | E23: ='Cash-Flow Bridge'!E20 | F23: ='Cash-Flow Bridge'!F20 | G23: ='Cash-Flow Bridge'!G20 | H23: ='Cash-Flow Bridge'!H20
A24: Net Mandatory Debt Service (= MAX(0, gross repayments - gross proceeds)) | D24: =MAX(0,D23-D22) | E24: =MAX(0,E23-E22) | F24: =MAX(0,F23-F22) | G24: =MAX(0,G23-G22) | H24: =MAX(0,H23-H22)
A25: C. Self-Funded Capacity Generated (FLOW, excludes opening liquidity) | D25: =D20-D24 | E25: =E20-E24 | F25: =F20-F24 | G25: =G20-G24 | H25: =H20-H24
A26: D. Debt-Funded Incremental Capacity (= MAX(0, proceeds - repayments); never gross issuance) | D26: =MAX(0,D22-D23) | E26: =MAX(0,E22-E23) | F26: =MAX(0,F22-F23) | G26: =MAX(0,G22-G23) | H26: =MAX(0,H22-H23)
A27: E. TOTAL GROSS FUNDING CAPACITY (Opening Liquidity + C + D) | D27: =D21+D25+D26 | E27: =E21+E25+E26 | F27: =F21+F25+F26 | G27: =G21+G25+G26 | H27: =H21+H25+H26
A28: Share Repurchases | D28: ='Cash-Flow Bridge'!D18 | E28: ='Cash-Flow Bridge'!E18 | F28: ='Cash-Flow Bridge'!F18 | G28: ='Cash-Flow Bridge'!G18 | H28: ='Cash-Flow Bridge'!H18
A29: Strategic Investment (none modeled this round) | D29: 0 | E29: 0 | F29: 0 | G29: 0 | H29: 0
A30: Voluntary Debt Reduction (none modeled this round) | D30: 0 | E30: 0 | F30: 0 | G30: 0 | H30: 0
A31: Other Discretionary Uses (none modeled this round) | D31: 0 | E31: 0 | F31: 0 | G31: 0 | H31: 0
A32: F. TOTAL DISCRETIONARY DEPLOYMENT | D32: =D28+D29+D30+D31 | E32: =E28+E29+E30+E31 | F32: =F28+F29+F30+F31 | G32: =G28+G29+G30+G31 | H32: =H28+H29+H30+H31
A33: Forward Debt-Repayment Reserve (next year's net debt service; FY2030 is a documented FY2031 proxy) | D33: =E24 | E33: =F24 | F33: =G24 | G33: =H24 | H33: =H24
A34: G. REMAINING DEPLOYABLE HEADROOM (stock, = MAX(0, E - F - forward reserve)) | D34: =MAX(0,D27-D32-D33) | E34: =MAX(0,E27-E32-E33) | F34: =MAX(0,F27-F32-F33) | G34: =MAX(0,G27-G32-G33) | H34: =MAX(0,H27-H32-H33)
A35: Ending Excess Liquidity (independent cross-check: = G + forward reserve) | D35: =MAX(0,'Cash-Flow Bridge'!D24-D9) | E35: =MAX(0,'Cash-Flow Bridge'!E24-E9) | F35: =MAX(0,'Cash-Flow Bridge'!F24-F9) | G35: =MAX(0,'Cash-Flow Bridge'!G24-G9) | H35: =MAX(0,'Cash-Flow Bridge'!H24-H9)
A36: DEPRECATED: Mandatory Debt Uses (v1, = gross repayments, double-subtracted -- see evidence doc) | D36: =D24 | E36: =E24 | F36: =F24 | G36: =G24 | H36: =H24
A37: DEPRECATED: Self-Funded Gross Capacity (v1-style, includes opening liquidity -- never labeled 'generated') | D37: =D21+D25 | E37: =E21+E25 | F37: =F21+F25 | G37: =G21+G25 | H37: =H21+H25
A39: Independent proof: Ending Excess Liquidity (from ending cash) equals Remaining Deployable Headroom PLUS the Forward Debt-Repayment Reserve, for every year -- confirming no dollar is counted in both headroom and deployment/reserve.
A41: CUMULATIVE CAPACITY RECONCILIATION, FY2026-FY2030 (STATIC reference, all scenarios -- from target_cash.capacity_taxonomy; NEVER a sum of per-year ending balances)
A42: Scenario | B42: A. Cumulative Self-Funded Generation | C42: B. Cumulative Debt-Funded Capacity | D42: C. Opening Excess Liquidity (horizon start) | E42: D. Cumulative Discretionary Deployment | F42: E. Terminal Remaining Headroom | G42: Ending Reserve Movement | H42: Terminal Forward Debt-Repayment Reserve (FY2031 proxy) | I42: Gross Horizon Funding, Before Reserve Adjustments (C+A+B) -- NOT net accessible capacity | J42: NET Horizon Deployable Capacity (Gross - Reserve Mvmt - Terminal Forward Reserve) | K42: Reconciles To (D+E)
A43: Base | B43: 6990.8 | C43: 0 | D43: 2313.2 | E43: 2796.3 | F43: 6378.7 | G43: 128.9 | H43: 0 | I43: 9303.9 | J43: 9175 | K43: 9175
A44: Upside | B44: 6276.8 | C44: 0 | D44: 2250.3 | E44: 5377.2 | F44: 2043.5 | G44: 406.4 | H44: 700 | I44: 8527.1 | J44: 7420.7 | K44: 7420.7
A45: Downside | B45: 2669.2 | C45: 1000 | D45: 2423.2 | E45: 0 | F45: 6387.5 | G45: -295.2 | H45: 0 | I45: 6092.3 | J45: 6387.5 | K45: 6387.5

Sheet Capital Allocation
A1: Capital Allocation Waterfall (LIVE, driven by Sheet 6 selector)
A2: Selected scenario: | B2: ='Forecast Assumptions'!$C$2
A3: Order of operations: 1) Operating cash generation 2) CapEx 3) Dividends 4) Minimum cash preservation 5) Scheduled debt 6) Incremental financing (always $0) 7) Discretionary repurchases 8) Ending cash.
A5: Waterfall Step | D5: FY2026 | E5: FY2027 | F5: FY2028 | G5: FY2029 | H5: FY2030
A6: Beginning Cash | D6: ='Cash-Flow Bridge'!D22 | E6: ='Cash-Flow Bridge'!E22 | F6: ='Cash-Flow Bridge'!F22 | G6: ='Cash-Flow Bridge'!G22 | H6: ='Cash-Flow Bridge'!H22
A7: 1. + Operating Cash Generation (CFO) | D7: ='Cash-Flow Bridge'!D11 | E7: ='Cash-Flow Bridge'!E11 | F7: ='Cash-Flow Bridge'!F11 | G7: ='Cash-Flow Bridge'!G11 | H7: ='Cash-Flow Bridge'!H11
A8: 2. + Capital Expenditures (CFI) | D8: ='Cash-Flow Bridge'!D14 | E8: ='Cash-Flow Bridge'!E14 | F8: ='Cash-Flow Bridge'!F14 | G8: ='Cash-Flow Bridge'!G14 | H8: ='Cash-Flow Bridge'!H14
A9: 3. - Dividends | D9: =-'Cash-Flow Bridge'!D16 | E9: =-'Cash-Flow Bridge'!E16 | F9: =-'Cash-Flow Bridge'!F16 | G9: =-'Cash-Flow Bridge'!G16 | H9: =-'Cash-Flow Bridge'!H16
A10: 4. Checkpoint: Cash Above Min. Buffer (no movement) | D10: =(D6+D7+D8+D9)-'Investment Capacity'!D9 | E10: =(E6+E7+E8+E9)-'Investment Capacity'!E9 | F10: =(F6+F7+F8+F9)-'Investment Capacity'!F9 | G10: =(G6+G7+G8+G9)-'Investment Capacity'!G9 | H10: =(H6+H7+H8+H9)-'Investment Capacity'!H9
A11: 5. +/- Scheduled Debt (proceeds - repayments) | D11: ='Cash-Flow Bridge'!D19-'Cash-Flow Bridge'!D20 | E11: ='Cash-Flow Bridge'!E19-'Cash-Flow Bridge'!E20 | F11: ='Cash-Flow Bridge'!F19-'Cash-Flow Bridge'!F20 | G11: ='Cash-Flow Bridge'!G19-'Cash-Flow Bridge'!G20 | H11: ='Cash-Flow Bridge'!H19-'Cash-Flow Bridge'!H20
A12: 5b. Checkpoint: DEPLOYABLE CAPACITY | D12: =MAX(0,((D6+D7+D8+D9)+D11)-'Investment Capacity'!D9-'Investment Capacity'!D10) | E12: =MAX(0,((E6+E7+E8+E9)+E11)-'Investment Capacity'!E9-'Investment Capacity'!E10) | F12: =MAX(0,((F6+F7+F8+F9)+F11)-'Investment Capacity'!F9-'Investment Capacity'!F10) | G12: =MAX(0,((G6+G7+G8+G9)+G11)-'Investment Capacity'!G9-'Investment Capacity'!G10) | H12: =MAX(0,((H6+H7+H8+H9)+H11)-'Investment Capacity'!H9-'Investment Capacity'!H10)
A13: 6. + Incremental Financing (always $0) | D13: 0 | E13: 0 | F13: 0 | G13: 0 | H13: 0
A14: 7. - Discretionary Repurchases | D14: =-'Cash-Flow Bridge'!D18 | E14: =-'Cash-Flow Bridge'!E18 | F14: =-'Cash-Flow Bridge'!F18 | G14: =-'Cash-Flow Bridge'!G18 | H14: =-'Cash-Flow Bridge'!H18
A15: 7b. - Mgmt-Selected Deployment (always $0) | D15: 0 | E15: 0 | F15: 0 | G15: 0 | H15: 0
A16: 8. = Ending Cash | D16: =((D6+D7+D8+D9)+D11)+D13+D14+D15 | E16: =((E6+E7+E8+E9)+E11)+E13+E14+E15 | F16: =((F6+F7+F8+F9)+F11)+F13+F14+F15 | G16: =((G6+G7+G8+G9)+G11)+G13+G14+G15 | H16: =((H6+H7+H8+H9)+H11)+H13+H14+H15
A18: No-Double-Counting Proof
A19: Ending Cash (Sheet 8) matches Step 8 above? | D19: =IF(ROUND('Cash-Flow Bridge'!D24-D16,2)=0,"OK","MISMATCH") | E19: =IF(ROUND('Cash-Flow Bridge'!E24-E16,2)=0,"OK","MISMATCH") | F19: =IF(ROUND('Cash-Flow Bridge'!F24-F16,2)=0,"OK","MISMATCH") | G19: =IF(ROUND('Cash-Flow Bridge'!G24-G16,2)=0,"OK","MISMATCH") | H19: =IF(ROUND('Cash-Flow Bridge'!H24-H16,2)=0,"OK","MISMATCH")

Sheet DCF Valuation
A1: DCF Valuation -- Scenario-Based Model (NOT Investment Advice)
A2: Selected scenario: | B2: ='Forecast Assumptions'!$C$2
A3: Illustrative WACC inputs below (yellow) -- no live market-data source is available to this project (SEC filings only); see Sheet 15 (Limitations).
A5: WACC Components (scenario-invariant)
A6: Risk-Free Rate | B6: 0.045
A7: Equity Risk Premium | B7: 0.055
A8: Beta | B8: 1
A9: Target Equity Weight | B9: 0.85
A10: Target Debt Weight | B10: 0.15
A11: Pre-Tax Cost of Debt | B11: 0.031
A12: Tax Rate (for WACC) | B12: 0.222
A13: Terminal Growth Rate | B13: 0.025
A15: Cost of Equity (CAPM) | B15: =B6+B8*B7
A16: After-Tax Cost of Debt | B16: =B11*(1-B12)
A17: WACC | B17: =B15*B9+B16*B10
A19: Unlevered Free Cash Flow | D19: FY2026 | E19: FY2027 | F19: FY2028 | G19: FY2029 | H19: FY2030
A20: NOPAT (EBIT x (1-tax)) | D20: ='Scenario Forecast'!D11*(1-(IF('Forecast Assumptions'!$C$2="Base",'Forecast Assumptions'!D9,IF('Forecast Assumptions'!$C$2="Upside",'Forecast Assumptions'!J9,'Forecast Assumptions'!P9)))) | E20: ='Scenario Forecast'!E11*(1-(IF('Forecast Assumptions'!$C$2="Base",'Forecast Assumptions'!E9,IF('Forecast Assumptions'!$C$2="Upside",'Forecast Assumptions'!K9,'Forecast Assumptions'!Q9)))) | F20: ='Scenario Forecast'!F11*(1-(IF('Forecast Assumptions'!$C$2="Base",'Forecast Assumptions'!F9,IF('Forecast Assumptions'!$C$2="Upside",'Forecast Assumptions'!L9,'Forecast Assumptions'!R9)))) | G20: ='Scenario Forecast'!G11*(1-(IF('Forecast Assumptions'!$C$2="Base",'Forecast Assumptions'!G9,IF('Forecast Assumptions'!$C$2="Upside",'Forecast Assumptions'!M9,'Forecast Assumptions'!S9)))) | H20: ='Scenario Forecast'!H11*(1-(IF('Forecast Assumptions'!$C$2="Base",'Forecast Assumptions'!H9,IF('Forecast Assumptions'!$C$2="Upside",'Forecast Assumptions'!N9,'Forecast Assumptions'!T9))))
A21: + D&A Add-back | D21: ='Cash-Flow Bridge'!D9 | E21: ='Cash-Flow Bridge'!E9 | F21: ='Cash-Flow Bridge'!F9 | G21: ='Cash-Flow Bridge'!G9 | H21: ='Cash-Flow Bridge'!H9
A22: + Other Operating CF | D22: ='Cash-Flow Bridge'!D10 | E22: ='Cash-Flow Bridge'!E10 | F22: ='Cash-Flow Bridge'!F10 | G22: ='Cash-Flow Bridge'!G10 | H22: ='Cash-Flow Bridge'!H10
A23: - CapEx | D23: =-'Cash-Flow Bridge'!D12 | E23: =-'Cash-Flow Bridge'!E12 | F23: =-'Cash-Flow Bridge'!F12 | G23: =-'Cash-Flow Bridge'!G12 | H23: =-'Cash-Flow Bridge'!H12
A24: +/- Working Capital Cash Impact | D24: ='Cash-Flow Bridge'!D6+'Cash-Flow Bridge'!D8 | E24: ='Cash-Flow Bridge'!E6+'Cash-Flow Bridge'!E8 | F24: ='Cash-Flow Bridge'!F6+'Cash-Flow Bridge'!F8 | G24: ='Cash-Flow Bridge'!G6+'Cash-Flow Bridge'!G8 | H24: ='Cash-Flow Bridge'!H6+'Cash-Flow Bridge'!H8
A25: Unlevered FCF (Total) | D25: =D20+D21+D22+D23+D24 | E25: =E20+E21+E22+E23+E24 | F25: =F20+F21+F22+F23+F24 | G25: =G20+G21+G22+G23+G24 | H25: =H20+H21+H22+H23+H24
A26: Discount Factor | D26: =1/(1+$B$17)^1 | E26: =1/(1+$B$17)^2 | F26: =1/(1+$B$17)^3 | G26: =1/(1+$B$17)^4 | H26: =1/(1+$B$17)^5
A27: PV of UFCF | D27: =D25*D26 | E27: =E25*E26 | F27: =F25*F26 | G27: =G25*G26 | H27: =H25*H26
A29: Valuation Bridge
A30: PV of Explicit-Period UFCF (FY2026-FY2030) | B30: =SUM(D27:H27)
A31: Terminal-Year UFCF (FY2030) | B31: =H25
A32: Terminal Value (undiscounted, Gordon Growth) | B32: =B31*(1+B13)/($B$17-B13)
A33: PV of Terminal Value | B33: =B32/(1+$B$17)^5
A34: Enterprise Value | B34: =B30+B33
A35: Net Debt (FY2025 actual: total_debt_gaap - cash) | B35: 8855
A36: Equity Value | B36: =B34-B35
A37: Diluted Shares (FY2025 actual, millions) | B37: 455.6
A38: IMPLIED VALUE PER SHARE | B38: =B36/B37
A41: All-Scenario DCF Comparison (STATIC reference -- from target_cash.valuation, same WACC/growth)
A42: Scenario | B42: Enterprise Value | C42: Equity Value | D42: Implied Value/Share
A43: Base | B43: 57736.3 | C43: 48881.3 | D43: 107.29
A44: Upside | B44: 71873.7 | C44: 63018.7 | D44: 138.32
A45: Downside | B45: 36898.6 | C45: 28043.6 | D45: 61.55

Sheet Sensitivities
A1: Sensitivities (Static Dry-Run Output)
A3: Driver: revenue_growth_pct (Base scenario, FY2030 impact)
A4: Delta | B4: CFO | C4: FCF | D4: Ending Cash | E4: Legacy Gross Capacity (DEPRECATED) | F4: Legacy Cumulative (DEPRECATED)
A5: -1 | B5: 7380.6 | C5: 3608.6 | D5: 9344.6 | E5: 6060.4 | F5: 6060.4
A6: -0.5 | B6: 7571.3 | C6: 3704 | D6: 9512.4 | E6: 6186.9 | F6: 6186.9
A7: 0 | B7: 7765.8 | C7: 3801.3 | D7: 9682.5 | E7: 6315 | F7: 6315
A8: 0.5 | B8: 7964.3 | C8: 3900.7 | D8: 9854.9 | E8: 6444.6 | F8: 6444.6
A9: 1 | B9: 8166.7 | C9: 4002 | D9: 10029.7 | E9: 6575.7 | F9: 6575.7
A11: Driver: gross_margin_pct (Base scenario, FY2030 impact)
A12: Delta | B12: CFO | C12: FCF | D12: Ending Cash | E12: Legacy Gross Capacity (DEPRECATED) | F12: Legacy Cumulative (DEPRECATED)
A13: -0.5 | B13: 7338.4 | C13: 3373.9 | D13: 8477.7 | E13: 4939.2 | F13: 4939.2
A14: -0.25 | B14: 7552.1 | C14: 3587.6 | D14: 9080.1 | E14: 5627.1 | F14: 5627.1
A15: 0 | B15: 7765.8 | C15: 3801.3 | D15: 9682.5 | E15: 6315 | F15: 6315
A16: 0.25 | B16: 7979.6 | C16: 4015.1 | D16: 10284.9 | E16: 7002.9 | F16: 7002.9
A17: 0.5 | B17: 8193.3 | C17: 4228.8 | D17: 10887.2 | E17: 7690.8 | F17: 7690.8
A19: Driver: sga_pct_of_revenue (Base scenario, FY2030 impact)
A20: Delta | B20: CFO | C20: FCF | D20: Ending Cash | E20: Legacy Gross Capacity (DEPRECATED) | F20: Legacy Cumulative (DEPRECATED)
A21: -0.5 | B21: 8194.2 | C21: 4229.7 | D21: 10942.4 | E21: 7746.3 | F21: 7746.3
A22: -0.25 | B22: 7980 | C22: 4015.5 | D22: 10312.4 | E22: 7030.7 | F22: 7030.7
A23: 0 | B23: 7765.8 | C23: 3801.3 | D23: 9682.5 | E23: 6315 | F23: 6315
A24: 0.25 | B24: 7551.6 | C24: 3587.1 | D24: 9052.5 | E24: 5599.4 | F24: 5599.4
A25: 0.5 | B25: 7337.4 | C25: 3373 | D25: 8422.5 | E25: 4883.7 | F25: 4883.7
A27: Driver: capex_pct_of_revenue (Base scenario, FY2030 impact)
A28: Delta | B28: CFO | C28: FCF | D28: Ending Cash | E28: Legacy Gross Capacity (DEPRECATED) | F28: Legacy Cumulative (DEPRECATED)
A29: -0.5 | B29: 7765.8 | C29: 4352 | D29: 11301.9 | E29: 8154.8 | F29: 8154.8
A30: -0.25 | B30: 7765.8 | C30: 4076.7 | D30: 10492.2 | E30: 7234.9 | F30: 7234.9
A31: 0 | B31: 7765.8 | C31: 3801.3 | D31: 9682.5 | E31: 6315 | F31: 6315
A32: 0.25 | B32: 7765.8 | C32: 3526 | D32: 8872.7 | E32: 5395.2 | F32: 5395.2
A33: 0.5 | B33: 7765.8 | C33: 3250.7 | D33: 8063 | E33: 4475.3 | F33: 4475.3
A35: Driver: inventory_pct_of_revenue (Base scenario, FY2030 impact)
A36: Delta | B36: CFO | C36: FCF | D36: Ending Cash | E36: Legacy Gross Capacity (DEPRECATED) | F36: Legacy Cumulative (DEPRECATED)
A37: -1 | B37: 7776.7 | C37: 3812.2 | D37: 10343.2 | E37: 6980.1 | F37: 6980.1
A38: -0.5 | B38: 7771.3 | C38: 3806.8 | D38: 10012.8 | E38: 6647.6 | F38: 6647.6
A39: 0 | B39: 7765.8 | C39: 3801.3 | D39: 9682.5 | E39: 6315 | F39: 6315
A40: 0.5 | B40: 7760.4 | C40: 3795.9 | D40: 9352.1 | E40: 5982.5 | F40: 5982.5
A41: 1 | B41: 7754.9 | C41: 3790.4 | D41: 9021.7 | E41: 5649.9 | F41: 5649.9
A43: Driver: min_cash_buffer_pct_of_revenue (Base scenario, FY2030 impact)
A44: Delta | B44: CFO | C44: FCF | D44: Ending Cash | E44: Legacy Gross Capacity (DEPRECATED) | F44: Legacy Cumulative (DEPRECATED)
A45: -1 | B45: 7765.8 | C45: 3801.3 | D45: 9682.5 | E45: 7416.3 | F45: 7416.3
A46: -0.5 | B46: 7765.8 | C46: 3801.3 | D46: 9682.5 | E46: 6865.6 | F46: 6865.6
...

Sheet Source & Lineage
A1: Source & Lineage
A3: Forecast information cutoff: 2026-03-11 (accession 0000027419-26-000016)
A5: Accession | B5: Form | C5: Period of Report | D5: Filed At
A6: 0000027419-22-000007 | B6: 10-K | C6: 2022-01-29 | D6: 2022-03-09
A7: 0000027419-23-000015 | B7: 10-K | C7: 2023-01-28 | D7: 2023-03-08
A8: 0000027419-24-000032 | B8: 10-K | C8: 2024-02-03 | D8: 2024-03-13
A9: 0000027419-25-000018 | B9: 10-K | C9: 2025-02-01 | D9: 2025-03-12
A10: 0000027419-25-000101 | B10: 10-Q | C10: 2025-05-03 | D10: 2025-05-30
A11: 0000027419-25-000118 | B11: 10-Q | C11: 2025-08-02 | D11: 2025-08-29
A12: 0000027419-25-000126 | B12: 10-Q | C12: 2025-11-01 | D12: 2025-11-26
A13: 0000027419-26-000016 | B13: 10-K | C13: 2026-01-31 | D13: 2026-03-11
A16: Lineage: every forecast fact traces to a historical annual_facts anchor, a prior forecast fact, or a forecast_assumptions row (1,533 forecast_lineage rows persisted; see docs/milestone_3_forecast_schema_proposal.md and the forecast_lineage table).

Sheet Validation Summary
A1: Validation Summary
A3: Forecast Engine: 21 named checks
A4: Check | B4: Rows | C4: PASS | D4: FAIL | E4: WARNING
A5: assumption_completeness | B5: 3 | C5: 3 | D5: 0 | E5: 0
A6: capital_allocation_waterfall_reconciliation | B6: 15 | C6: 15 | D6: 0 | E6: 0
A7: cash_roll_forward | B7: 15 | C7: 15 | D7: 0 | E7: 0
A8: cfo_construction | B8: 15 | C8: 15 | D8: 0 | E8: 0
A9: cumulative_capacity_no_double_counting | B9: 3 | C9: 3 | D9: 0 | E9: 0
A10: debt_roll_forward | B10: 15 | C10: 15 | D10: 0 | E10: 0
A11: eps_consistency | B11: 15 | C11: 15 | D11: 0 | E11: 0
A12: fcf_calc | B12: 15 | C12: 15 | D12: 0 | E12: 0
A13: gross_profit_calc | B13: 15 | C13: 15 | D13: 0 | E13: 0
A14: information_cutoff_compliance | B14: 1 | C14: 1 | D14: 0 | E14: 0
A15: lineage_completeness | B15: 3 | C15: 3 | D15: 0 | E15: 0
A16: minimum_cash_compliance | B16: 15 | C16: 15 | D16: 0 | E16: 0
... A25: working_capital_sign_checks | B25: 15 | C25: 15 | D25: 0 | E25: 0
A27: TOTAL: 229 results, 0 failures
A29: DCF Valuation: 6 named checks
A30: Check | B30: Rows | C30: PASS | D30: FAIL
A31: ufcf_reconciles_to_levered_fcf | B31: 15 | C31: 15 | D31: 0
A32: terminal_value_period_consistency | B32: 3 | C32: 3 | D32: 0
A33: no_debt_or_lease_double_counting | B33: 3 | C33: 3 | D33: 0
A34: valuation_date_consistency | B34: 3 | C34: 3 | D34: 0
A35: wacc_exceeds_terminal_growth | B35: 3 | C35: 3 | D35: 0
A36: wacc_and_terminal_growth_scenario_invariant | B36: 1 | C36: 1 | D36: 0
A38: TOTAL: 28 results, 0 failures
A40: Corrected Capacity Taxonomy (Milestone 9 v2 correction): 19 named checks
A41: Check | B41: Rows | C41: PASS | D41: FAIL | E41: WARNING
A42: annual_source_use_reconciliation | B42: 15 | C42: 15 | D42: 0 | E42: 0
A43: capacity_accounted_for_reconciliation | B43: 3 | C43: 3 | D43: 0 | E43: 0
A44: capacity_mutually_exclusive | B44: 15 | C44: 15 | D44: 0 | E44: 0
A45: cumulative_deployment_includes_repurchases | B45: 3 | C45: 3 | D45: 0 | E45: 0
A46: cumulative_excludes_repeated_balances | B46: 3 | C46: 3 | D46: 0 | E46: 0
A47: debt_funded_capacity_excludes_gross_issuance | B47: 15 | C47: 15 | D47: 0 | E47: 0
A48: debt_netting_mutually_exclusive | B48: 15 | C48: 15 | D48: 0 | E48: 0
A49: ending_cash_above_buffer_or_flagged | B49: 15 | C49: 15 | D49: 0 | E49: 0
A50: forward_reserve_terminal_proxy_documented | B50: 3 | C50: 3 | D50: 0 | E50: 0
A51: headroom_deducts_forward_reserve | B51: 15 | C51: 15 | D51: 0 | E51: 0
A52: headroom_never_negative | B52: 15 | C52: 15 | D52: 0 | E52: 0
A53: mandatory_debt_not_double_deducted | B53: 15 | C53: 15 | D53: 0 | E53: 0
...

Sheet Limitations
A1: Limitations
A3: - investing_cash_flow is modeled as exactly -CapEx; no driver exists for other historical investing items.
A4: - No FX translation effect is modeled (implicitly zero).
A5: - The near-term debt repayment reserve is proxied by each year's own fixed repayment assumption -- no disclosed maturity ladder exists.
A6: - 'Other operating cash adjustments' is a single flat scenario assumption, not decomposed into stock-comp/deferred-tax/other sub-components.
A7: - The seasonality stress overlay is grounded in exactly ONE year of real quarterly evidence (FY2025).
A8: - The minimum-cash-buffer comparison evaluates 5 policies but endorses none as final.
A9: - DCF WACC components (risk-free rate, equity risk premium, beta) are illustrative, general-market inputs -- no live market-data source is in the registered source set.
A10: - DCF capital-structure weights are a target/policy split, not a market-value weight (which would require the market value of equity -- circular with the equity value being estimated).
A11: - This workbook is a scenario-based model, NOT investment advice, a price target, or a prediction of Target's actual future results or stock price.
A12: - CapEx is modeled as a % of revenue with no maintenance-vs-growth split, since Target discloses no such split.
A13: - Dividends are modeled via a $/share growth proxy, not a disclosed per-share dividend policy statement.
... A17: - v2 finance-semantics correction: debt_funded_incremental_capacity previously equaled gross debt proceeds, mislabeling capacity even when the same cash was simultaneously repaid. It is now the NET of proceeds over repayments; the offsetting net_mandatory_debt_service is subtracted from self_funded_capacity_generated, which now excludes opening_excess_liquidity entirely (a stock is never labeled 'generated'). Remaining Deployable Headroom now also deducts a forward debt-repayment reserve, proxied for the terminal FY2030 year since FY2031 is outside the forecast horizon. See docs/investment_capacity_correction_evidence.md.
